Workbook

Sheet START HERE
B2: THE FIRSTS FUND — EQUITY RESEARCH WORKSHEET
B3: What still needs researching before Phase 2. FinQuest 2026 · Team Firsts
B6: WHY THIS EXISTS
B7: The problem | C7: Fund weights = CONVICTION / VOLATILITY. Volatility came from 1,293 days of real price data. Conviction (88 for ICTSI, 70 for Grab) was assigned by judgment — no financial statement was read.
B8: What that means | C8: Half the weighting formula is empirically grounded. Half is not. This workbook closes that gap.
B9: Also unverified | C9: The Buildout Test gates (B1 liquidity/capex, B2 ADTV & free float, B3 solvency, B4 conduct) were applied judgmentally. Only Grab B3 was actually tested against financials.
B11: HOW TO USE IT
B12: 1. Split the work | C12: Three people, one company each. Priority order: ICTSI, ACEN, Vertiv — largest PH position, the DOE-target anchor, and the highest-volatility holding.
B13: 2. Fill the BLUE cells only | C13: Blue = you type a number or a note. Black = calculated automatically. Do not overwrite black cells.
B14: 3. Cite everything | C14: Every number needs a source cell: document name, page or section. "Annual Report 2025, p.87, Note 14".
B15: 4. Check the SCORECARD tab | C15: Conviction scores recompute automatically as you fill in each company sheet.
B16: 5. Re-run the engine | C16: Open firsts_fund_engine.py, replace the conviction numbers in HOLDINGS, re-run. Weights update.
B18: REALISTIC SCOPE
B19: Time per company | C19: 2-3 hours. Download annual report, pull ~12 numbers, compute 6 ratios.
B20: If you only do three | C20: You can honestly say: "We ran the full FIRST rubric on our three highest-conviction names; here is the working." That is far stronger than a clean table nobody tested.
B21: Do NOT fabricate | C21: A made-up ROIC collapses the moment a judge asks how you got it. Leave a cell blank and say "not yet verified" instead.
B23: LEGEND
B24: Blue text | C24: You fill this in
B25: Black text | C25: Calculated — do not edit
B26: Yellow fill | C26: Key output that feeds the scorecard

Sheet WHERE TO GET IT
B2: WHERE TO FIND THE FILINGS
B3: All free. No terminal required.
B5: Ticker | C5: Company | D5: Exchange / Source | E5: Document to download
B6: ICT | C6: Int'l Container Terminal Services | D6: PSE EDGE (edge.pse.com.ph) | E6: Annual Report 2025 + SEC Form 17-A
B7: CNPF | C7: Century Pacific Food | D7: PSE EDGE | E7: Annual Report 2025 + 17-A
B8: ACEN | C8: ACEN Corporation | D8: PSE EDGE | E8: Annual Report 2025 + 17-A + sustainability report (for MW)
B9: D05 | C9: DBS Group Holdings | D9: SGXNet / dbs.com investor relations | E9: Annual Report 2025
B10: Q0F | C10: IHH Healthcare | D10: SGXNet / Bursa Malaysia | E10: Annual Report 2025
B11: SU | C11: Schneider Electric | D11: se.com investor relations | E11: Universal Registration Document 2025
B12: TSM | C12: Taiwan Semiconductor | D12: SEC EDGAR (form 20-F) | E12: 20-F FY2025 + quarterly capex guidance
B13: VRT | C13: Vertiv Holdings | D13: SEC EDGAR (form 10-K) | E13: 10-K FY2025 + backlog disclosure
B14: SE | C14: Sea Limited | D14: SEC EDGAR (form 20-F) | E14: 20-F FY2025
B15: GRAB | C15: Grab Holdings | D15: SEC EDGAR (form 20-F) | E15: 20-F FY2025 [B3 already verified]
B17: TIP | C17: The investor presentation is ~80% of what you need in 40 slides. Start there, then use the annual report to confirm exact figures.

Sheet SCORECARD
B2: CONVICTION SCORECARD
B3: Updates automatically as each company sheet is filled in. Blank = not yet researched.
B5: Ticker | C5: Company | D5: Assigned (current) | E5: Derived (new) | F5: Difference | G5: Status
B6: ICT | C6: Int'l Container Terminal Services | D6: 88 | E6: =IF('ICT'!D42="","",'ICT'!D42) | F6: =IF(E6="","",E6-D6) | G6: =IF(E6="","NOT YET RESEARCHED","done")
B7: ACEN | C7: ACEN Corporation | D7: 80 | E7: =IF('ACEN'!D42="","",'ACEN'!D42) | F7: =IF(E7="","",E7-D7) | G7: =IF(E7="","NOT YET RESEARCHED","done")
B8: VRT | C8: Vertiv Holdings | D8: 76 | E8: =IF('VRT'!D42="","",'VRT'!D42) | F8: =IF(E8="","",E8-D8) | G8: =IF(E8="","NOT YET RESEARCHED","done")
B9: CNPF | C9: Century Pacific Food | D9: 78 | E9: =IF('CNPF'!D42="","",'CNPF'!D42) | F9: =IF(E9="","",E9-D9) | G9: =IF(E9="","NOT YET RESEARCHED","done")
B10: D05 | C10: DBS Group Holdings | D10: 85 | E10: =IF('D05'!D42="","",'D05'!D42) | F10: =IF(E10="","",E10-D10) | G10: =IF(E10="","NOT YET RESEARCHED","done")
B11: Q0F | C11: IHH Healthcare | D11: 75 | E11: =IF('Q0F'!D42="","",'Q0F'!D42) | F11: =IF(E11="","",E11-D11) | G11: =IF(E11="","NOT YET RESEARCHED","done")
B12: SU | C12: Schneider Electric | D12: 82 | E12: =IF('SU'!D42="","",'SU'!D42) | F12: =IF(E12="","",E12-D12) | G12: =IF(E12="","NOT YET RESEARCHED","done")
B13: TSM | C13: Taiwan Semiconductor | D13: 86 | E13: =IF('TSM'!D42="","",'TSM'!D42) | F13: =IF(E13="","",E13-D13) | G13: =IF(E13="","NOT YET RESEARCHED","done")
B14: SE | C14: Sea Limited | D14: 72 | E14: =IF('SE'!D42="","",'SE'!D42) | F14: =IF(E14="","",E14-D14) | G14: =IF(E14="","NOT YET RESEARCHED","done")
B15: GRAB | C15: Grab Holdings | D15: 70 | E15: =IF('GRAB'!D42="","",'GRAB'!D42) | F15: =IF(E15="","",E15-D15) | G15: =IF(E15="","NOT YET RESEARCHED","done")
C17: Companies researched | E17: =COUNT(E6:E15)
C18: Target before Phase 2 (minimum) | E18: 3

Sheet ICT
B2: Int'l Container Terminal Services (ICT)
B3: Priority 1 · Fill BLUE cells only · every figure needs a source
B5: RAW FIGURES — pull these from the filing
B6: Revenue, latest FY | C6: currency mn | E6: Income statement
B7: Revenue, 3 years ago | C7: currency mn | E7: Income statement, comparatives
B8: EBIT (operating profit) | C8: currency mn | E8: Income statement
B9: EBITDA | C9: currency mn | E9: Income statement or MD&A
B10: Effective tax rate | C10: decimal e.g. 0.25 | E10: Tax note
B11: Net income | C11: currency mn | E11: Income statement
B12: Operating cash flow | C12: currency mn | E12: Cash flow statement
B13: Capital expenditure | C13: currency mn | E13: Cash flow statement — investing
B14: Total debt | C14: currency mn | E14: Balance sheet
B15: Cash & equivalents | C15: currency mn | E15: Balance sheet
B16: Total equity | C16: currency mn | E16: Balance sheet
B17: Interest expense | C17: currency mn | E17: Finance costs note
... B19: Free float | C19: % e.g. 0.35 | E19: Ownership / shareholding note
B21: COMPUTED RATIOS — do not edit, these calculate
B22: Revenue 3-yr CAGR | D22: =IFERROR((D6/D7)^(1/3)-1,"")
B23: ROIC (NOPAT / invested capital) | D23: =IFERROR(D8*(1-D10)/(D14+D16-D15),"")
B24: FCF conversion (OCF-capex)/NI | D24: =IFERROR((D12-D13)/D11,"")
B25: Net debt / EBITDA | D25: =IFERROR((D14-D15)/D9,"")
B26: EBIT interest cover | D26: =IFERROR(D8/D17,"")
B27: EV / EBITDA | D27: =IFERROR((D18+D14-D15)/D9,"")
B29: BUILDOUT TEST — the four gates, now actually tested
B30: B1 Buildout | C30: >=20% of revenue or 3-yr capex tied to a PUBLISHED capacity target | E30: PASS/FAIL + the actual %, and name the programme (e.g. DOE NREP, disclosed fab capex)
B31: B2 Liquidity | C31: 90-day ADTV >= PHP30M (PH) / USD5M (offshore); free float >=20% | E31: PASS/FAIL + the ADTV figure and its source
B32: B3 Solvency | C32: Net debt/EBITDA <=4.0x OR net cash; if net debt positive, interest cover >=2.5x | E32: PASS/FAIL — read it off the computed ratios above
B33: B4 Conduct | C33: No thermal coal >10% of revenue; no UNGC breach; CG disclosure | E33: PASS/FAIL + note any controversy found
B35: FIRST SCORE — replace the assigned score with a derived one
B36: Factor | C36: Weight | D36: Score 0-100 | E36: Evidence you are scoring on
B37: F — Future Relevance | C37: 0.25 | E37: Scale and duration of the buildout; order backlog or contracted capacity
B38: I — Impact on Youth | C38: 0.15 | E38: Directness of link to a named "first"; segment revenue if disclosed
B39: R — Resilient Finances | C39: 0.25 | E39: Use the ROIC, FCF conversion and leverage computed above
B40: S — Sensible Valuation | C40: 0.2 | E40: EV/EBITDA vs the company's own 5-year range
B41: T — Trust & Governance | C41: 0.15 | E41: Free float, related-party transactions, board independence
B42: WEIGHTED CONVICTION SCORE | D42: =IFERROR(SUMPRODUCT(C37:C41,D37:D41),"")
B44: Score currently assumed in the engine | D44: 88
B45: Difference | D45: =IFERROR(D42-D44,"")
B47: SOURCES USED
B48: Source 1
...

Sheet ACEN
B2: ACEN Corporation (ACEN)
B3: Priority 2 · Fill BLUE cells only · every figure needs a source
B5: RAW FIGURES — pull these from the filing
B6: Revenue, latest FY | C6: currency mn | E6: Income statement
B7: Revenue, 3 years ago | C7: currency mn | E7: Income statement, comparatives
B8: EBIT (operating profit) | C8: currency mn | E8: Income statement
B9: EBITDA | C9: currency mn | E9: Income statement or MD&A
B10: Effective tax rate | C10: decimal e.g. 0.25 | E10: Tax note
B11: Net income | C11: currency mn | E11: Income statement
B12: Operating cash flow | C12: currency mn | E12: Cash flow statement
B13: Capital expenditure | C13: currency mn | E13: Cash flow statement — investing
B14: Total debt | C14: currency mn | E14: Balance sheet
B15: Cash & equivalents | C15: currency mn | E15: Balance sheet
B16: Total equity | C16: currency mn | E16: Balance sheet
B17: Interest expense | C17: currency mn | E17: Finance costs note
... B19: Free float | C19: % e.g. 0.35 | E19: Ownership / shareholding note
B21: COMPUTED RATIOS — do not edit, these calculate
B22: Revenue 3-yr CAGR | D22: =IFERROR((D6/D7)^(1/3)-1,"")
B23: ROIC (NOPAT / invested capital) | D23: =IFERROR(D8*(1-D10)/(D14+D16-D15),"")
B24: FCF conversion (OCF-capex)/NI | D24: =IFERROR((D12-D13)/D11,"")
B25: Net debt / EBITDA | D25: =IFERROR((D14-D15)/D9,"")
B26: EBIT interest cover | D26: =IFERROR(D8/D17,"")
B27: EV / EBITDA | D27: =IFERROR((D18+D14-D15)/D9,"")
B29: BUILDOUT TEST — the four gates, now actually tested
B30: B1 Buildout | C30: >=20% of revenue or 3-yr capex tied to a PUBLISHED capacity target | E30: PASS/FAIL + the actual %, and name the programme (e.g. DOE NREP, disclosed fab capex)
B31: B2 Liquidity | C31: 90-day ADTV >= PHP30M (PH) / USD5M (offshore); free float >=20% | E31: PASS/FAIL + the ADTV figure and its source
B32: B3 Solvency | C32: Net debt/EBITDA <=4.0x OR net cash; if net debt positive, interest cover >=2.5x | E32: PASS/FAIL — read it off the computed ratios above
B33: B4 Conduct | C33: No thermal coal >10% of revenue; no UNGC breach; CG disclosure | E33: PASS/FAIL + note any controversy found
B35: FIRST SCORE — replace the assigned score with a derived one
B36: Factor | C36: Weight | D36: Score 0-100 | E36: Evidence you are scoring on
B37: F — Future Relevance | C37: 0.25 | E37: Scale and duration of the buildout; order backlog or contracted capacity
B38: I — Impact on Youth | C38: 0.15 | E38: Directness of link to a named "first"; segment revenue if disclosed
B39: R — Resilient Finances | C39: 0.25 | E39: Use the ROIC, FCF conversion and leverage computed above
B40: S — Sensible Valuation | C40: 0.2 | E40: EV/EBITDA vs the company's own 5-year range
B41: T — Trust & Governance | C41: 0.15 | E41: Free float, related-party transactions, board independence
B42: WEIGHTED CONVICTION SCORE | D42: =IFERROR(SUMPRODUCT(C37:C41,D37:D41),"")
B44: Score currently assumed in the engine | D44: 80
B45: Difference | D45: =IFERROR(D42-D44,"")
B47: SOURCES USED
B48: Source 1
...

Sheet VRT
B2: Vertiv Holdings (VRT)
B3: Priority 3 · Fill BLUE cells only · every figure needs a source
B5: RAW FIGURES — pull these from the filing
B6: Revenue, latest FY | C6: currency mn | E6: Income statement
B7: Revenue, 3 years ago | C7: currency mn | E7: Income statement, comparatives
B8: EBIT (operating profit) | C8: currency mn | E8: Income statement
B9: EBITDA | C9: currency mn | E9: Income statement or MD&A
B10: Effective tax rate | C10: decimal e.g. 0.25 | E10: Tax note
B11: Net income | C11: currency mn | E11: Income statement
B12: Operating cash flow | C12: currency mn | E12: Cash flow statement
B13: Capital expenditure | C13: currency mn | E13: Cash flow statement — investing
B14: Total debt | C14: currency mn | E14: Balance sheet
B15: Cash & equivalents | C15: currency mn | E15: Balance sheet
B16: Total equity | C16: currency mn | E16: Balance sheet
B17: Interest expense | C17: currency mn | E17: Finance costs note
... B19: Free float | C19: % e.g. 0.35 | E19: Ownership / shareholding note
B21: COMPUTED RATIOS — do not edit, these calculate
B22: Revenue 3-yr CAGR | D22: =IFERROR((D6/D7)^(1/3)-1,"")
B23: ROIC (NOPAT / invested capital) | D23: =IFERROR(D8*(1-D10)/(D14+D16-D15),"")
B24: FCF conversion (OCF-capex)/NI | D24: =IFERROR((D12-D13)/D11,"")
B25: Net debt / EBITDA | D25: =IFERROR((D14-D15)/D9,"")
B26: EBIT interest cover | D26: =IFERROR(D8/D17,"")
B27: EV / EBITDA | D27: =IFERROR((D18+D14-D15)/D9,"")
B29: BUILDOUT TEST — the four gates, now actually tested
B30: B1 Buildout | C30: >=20% of revenue or 3-yr capex tied to a PUBLISHED capacity target | E30: PASS/FAIL + the actual %, and name the programme (e.g. DOE NREP, disclosed fab capex)
B31: B2 Liquidity | C31: 90-day ADTV >= PHP30M (PH) / USD5M (offshore); free float >=20% | E31: PASS/FAIL + the ADTV figure and its source
B32: B3 Solvency | C32: Net debt/EBITDA <=4.0x OR net cash; if net debt positive, interest cover >=2.5x | E32: PASS/FAIL — read it off the computed ratios above
B33: B4 Conduct | C33: No thermal coal >10% of revenue; no UNGC breach; CG disclosure | E33: PASS/FAIL + note any controversy found
B35: FIRST SCORE — replace the assigned score with a derived one
B36: Factor | C36: Weight | D36: Score 0-100 | E36: Evidence you are scoring on
B37: F — Future Relevance | C37: 0.25 | E37: Scale and duration of the buildout; order backlog or contracted capacity
B38: I — Impact on Youth | C38: 0.15 | E38: Directness of link to a named "first"; segment revenue if disclosed
B39: R — Resilient Finances | C39: 0.25 | E39: Use the ROIC, FCF conversion and leverage computed above
B40: S — Sensible Valuation | C40: 0.2 | E40: EV/EBITDA vs the company's own 5-year range
B41: T — Trust & Governance | C41: 0.15 | E41: Free float, related-party transactions, board independence
B42: WEIGHTED CONVICTION SCORE | D42: =IFERROR(SUMPRODUCT(C37:C41,D37:D41),"")
B44: Score currently assumed in the engine | D44: 76
B45: Difference | D45: =IFERROR(D42-D44,"")
B47: SOURCES USED
B48: Source 1
...

Sheet CNPF
B2: Century Pacific Food (CNPF)
B3: Priority 4 · Fill BLUE cells only · every figure needs a source
B5: RAW FIGURES — pull these from the filing
B6: Revenue, latest FY | C6: currency mn | E6: Income statement
B7: Revenue, 3 years ago | C7: currency mn | E7: Income statement, comparatives
B8: EBIT (operating profit) | C8: currency mn | E8: Income statement
B9: EBITDA | C9: currency mn | E9: Income statement or MD&A
B10: Effective tax rate | C10: decimal e.g. 0.25 | E10: Tax note
B11: Net income | C11: currency mn | E11: Income statement
B12: Operating cash flow | C12: currency mn | E12: Cash flow statement
B13: Capital expenditure | C13: currency mn | E13: Cash flow statement — investing
B14: Total debt | C14: currency mn | E14: Balance sheet
B15: Cash & equivalents | C15: currency mn | E15: Balance sheet
B16: Total equity | C16: currency mn | E16: Balance sheet
B17: Interest expense | C17: currency mn | E17: Finance costs note
... B19: Free float | C19: % e.g. 0.35 | E19: Ownership / shareholding note
B21: COMPUTED RATIOS — do not edit, these calculate
B22: Revenue 3-yr CAGR | D22: =IFERROR((D6/D7)^(1/3)-1,"")
B23: ROIC (NOPAT / invested capital) | D23: =IFERROR(D8*(1-D10)/(D14+D16-D15),"")
B24: FCF conversion (OCF-capex)/NI | D24: =IFERROR((D12-D13)/D11,"")
B25: Net debt / EBITDA | D25: =IFERROR((D14-D15)/D9,"")
B26: EBIT interest cover | D26: =IFERROR(D8/D17,"")
B27: EV / EBITDA | D27: =IFERROR((D18+D14-D15)/D9,"")
B29: BUILDOUT TEST — the four gates, now actually tested
B30: B1 Buildout | C30: >=20% of revenue or 3-yr capex tied to a PUBLISHED capacity target | E30: PASS/FAIL + the actual %, and name the programme (e.g. DOE NREP, disclosed fab capex)
B31: B2 Liquidity | C31: 90-day ADTV >= PHP30M (PH) / USD5M (offshore); free float >=20% | E31: PASS/FAIL + the ADTV figure and its source
B32: B3 Solvency | C32: Net debt/EBITDA <=4.0x OR net cash; if net debt positive, interest cover >=2.5x | E32: PASS/FAIL — read it off the computed ratios above
B33: B4 Conduct | C33: No thermal coal >10% of revenue; no UNGC breach; CG disclosure | E33: PASS/FAIL + note any controversy found
B35: FIRST SCORE — replace the assigned score with a derived one
B36: Factor | C36: Weight | D36: Score 0-100 | E36: Evidence you are scoring on
B37: F — Future Relevance | C37: 0.25 | E37: Scale and duration of the buildout; order backlog or contracted capacity
B38: I — Impact on Youth | C38: 0.15 | E38: Directness of link to a named "first"; segment revenue if disclosed
B39: R — Resilient Finances | C39: 0.25 | E39: Use the ROIC, FCF conversion and leverage computed above
B40: S — Sensible Valuation | C40: 0.2 | E40: EV/EBITDA vs the company's own 5-year range
B41: T — Trust & Governance | C41: 0.15 | E41: Free float, related-party transactions, board independence
B42: WEIGHTED CONVICTION SCORE | D42: =IFERROR(SUMPRODUCT(C37:C41,D37:D41),"")
B44: Score currently assumed in the engine | D44: 78
B45: Difference | D45: =IFERROR(D42-D44,"")
B47: SOURCES USED
B48: Source 1
...

Sheet D05
B2: DBS Group Holdings (D05)
B3: Priority 5 · Fill BLUE cells only · every figure needs a source
B5: RAW FIGURES — pull these from the filing
B6: Revenue, latest FY | C6: currency mn | E6: Income statement
B7: Revenue, 3 years ago | C7: currency mn | E7: Income statement, comparatives
B8: EBIT (operating profit) | C8: currency mn | E8: Income statement
B9: EBITDA | C9: currency mn | E9: Income statement or MD&A
B10: Effective tax rate | C10: decimal e.g. 0.25 | E10: Tax note
B11: Net income | C11: currency mn | E11: Income statement
B12: Operating cash flow | C12: currency mn | E12: Cash flow statement
B13: Capital expenditure | C13: currency mn | E13: Cash flow statement — investing
B14: Total debt | C14: currency mn | E14: Balance sheet
B15: Cash & equivalents | C15: currency mn | E15: Balance sheet
B16: Total equity | C16: currency mn | E16: Balance sheet
B17: Interest expense | C17: currency mn | E17: Finance costs note
... B19: Free float | C19: % e.g. 0.35 | E19: Ownership / shareholding note
B21: COMPUTED RATIOS — do not edit, these calculate
B22: Revenue 3-yr CAGR | D22: =IFERROR((D6/D7)^(1/3)-1,"")
B23: ROIC (NOPAT / invested capital) | D23: =IFERROR(D8*(1-D10)/(D14+D16-D15),"")
B24: FCF conversion (OCF-capex)/NI | D24: =IFERROR((D12-D13)/D11,"")
B25: Net debt / EBITDA | D25: =IFERROR((D14-D15)/D9,"")
B26: EBIT interest cover | D26: =IFERROR(D8/D17,"")
B27: EV / EBITDA | D27: =IFERROR((D18+D14-D15)/D9,"")
B29: BUILDOUT TEST — the four gates, now actually tested
B30: B1 Buildout | C30: >=20% of revenue or 3-yr capex tied to a PUBLISHED capacity target | E30: PASS/FAIL + the actual %, and name the programme (e.g. DOE NREP, disclosed fab capex)
B31: B2 Liquidity | C31: 90-day ADTV >= PHP30M (PH) / USD5M (offshore); free float >=20% | E31: PASS/FAIL + the ADTV figure and its source
B32: B3 Solvency | C32: Net debt/EBITDA <=4.0x OR net cash; if net debt positive, interest cover >=2.5x | E32: PASS/FAIL — read it off the computed ratios above
B33: B4 Conduct | C33: No thermal coal >10% of revenue; no UNGC breach; CG disclosure | E33: PASS/FAIL + note any controversy found
B35: FIRST SCORE — replace the assigned score with a derived one
B36: Factor | C36: Weight | D36: Score 0-100 | E36: Evidence you are scoring on
B37: F — Future Relevance | C37: 0.25 | E37: Scale and duration of the buildout; order backlog or contracted capacity
B38: I — Impact on Youth | C38: 0.15 | E38: Directness of link to a named "first"; segment revenue if disclosed
B39: R — Resilient Finances | C39: 0.25 | E39: Use the ROIC, FCF conversion and leverage computed above
B40: S — Sensible Valuation | C40: 0.2 | E40: EV/EBITDA vs the company's own 5-year range
B41: T — Trust & Governance | C41: 0.15 | E41: Free float, related-party transactions, board independence
B42: WEIGHTED CONVICTION SCORE | D42: =IFERROR(SUMPRODUCT(C37:C41,D37:D41),"")
B44: Score currently assumed in the engine | D44: 85
B45: Difference | D45: =IFERROR(D42-D44,"")
B47: SOURCES USED
B48: Source 1
...

Sheet Q0F
B2: IHH Healthcare (Q0F)
B3: Priority 6 · Fill BLUE cells only · every figure needs a source
B5: RAW FIGURES — pull these from the filing
B6: Revenue, latest FY | C6: currency mn | E6: Income statement
B7: Revenue, 3 years ago | C7: currency mn | E7: Income statement, comparatives
B8: EBIT (operating profit) | C8: currency mn | E8: Income statement
B9: EBITDA | C9: currency mn | E9: Income statement or MD&A
B10: Effective tax rate | C10: decimal e.g. 0.25 | E10: Tax note
B11: Net income | C11: currency mn | E11: Income statement
B12: Operating cash flow | C12: currency mn | E12: Cash flow statement
B13: Capital expenditure | C13: currency mn | E13: Cash flow statement — investing
B14: Total debt | C14: currency mn | E14: Balance sheet
B15: Cash & equivalents | C15: currency mn | E15: Balance sheet
B16: Total equity | C16: currency mn | E16: Balance sheet
B17: Interest expense | C17: currency mn | E17: Finance costs note
... B19: Free float | C19: % e.g. 0.35 | E19: Ownership / shareholding note
B21: COMPUTED RATIOS — do not edit, these calculate
B22: Revenue 3-yr CAGR | D22: =IFERROR((D6/D7)^(1/3)-1,"")
B23: ROIC (NOPAT / invested capital) | D23: =IFERROR(D8*(1-D10)/(D14+D16-D15),"")
B24: FCF conversion (OCF-capex)/NI | D24: =IFERROR((D12-D13)/D11,"")
B25: Net debt / EBITDA | D25: =IFERROR((D14-D15)/D9,"")
B26: EBIT interest cover | D26: =IFERROR(D8/D17,"")
B27: EV / EBITDA | D27: =IFERROR((D18+D14-D15)/D9,"")
B29: BUILDOUT TEST — the four gates, now actually tested
B30: B1 Buildout | C30: >=20% of revenue or 3-yr capex tied to a PUBLISHED capacity target | E30: PASS/FAIL + the actual %, and name the programme (e.g. DOE NREP, disclosed fab capex)
B31: B2 Liquidity | C31: 90-day ADTV >= PHP30M (PH) / USD5M (offshore); free float >=20% | E31: PASS/FAIL + the ADTV figure and its source
B32: B3 Solvency | C32: Net debt/EBITDA <=4.0x OR net cash; if net debt positive, interest cover >=2.5x | E32: PASS/FAIL — read it off the computed ratios above
B33: B4 Conduct | C33: No thermal coal >10% of revenue; no UNGC breach; CG disclosure | E33: PASS/FAIL + note any controversy found
B35: FIRST SCORE — replace the assigned score with a derived one
B36: Factor | C36: Weight | D36: Score 0-100 | E36: Evidence you are scoring on
B37: F — Future Relevance | C37: 0.25 | E37: Scale and duration of the buildout; order backlog or contracted capacity
B38: I — Impact on Youth | C38: 0.15 | E38: Directness of link to a named "first"; segment revenue if disclosed
B39: R — Resilient Finances | C39: 0.25 | E39: Use the ROIC, FCF conversion and leverage computed above
B40: S — Sensible Valuation | C40: 0.2 | E40: EV/EBITDA vs the company's own 5-year range
B41: T — Trust & Governance | C41: 0.15 | E41: Free float, related-party transactions, board independence
B42: WEIGHTED CONVICTION SCORE | D42: =IFERROR(SUMPRODUCT(C37:C41,D37:D41),"")
B44: Score currently assumed in the engine | D44: 75
B45: Difference | D45: =IFERROR(D42-D44,"")
B47: SOURCES USED
B48: Source 1
...

Sheet SU
B2: Schneider Electric (SU)
B3: Priority 7 · Fill BLUE cells only · every figure needs a source
B5: RAW FIGURES — pull these from the filing
B6: Revenue, latest FY | C6: currency mn | E6: Income statement
B7: Revenue, 3 years ago | C7: currency mn | E7: Income statement, comparatives
B8: EBIT (operating profit) | C8: currency mn | E8: Income statement
B9: EBITDA | C9: currency mn | E9: Income statement or MD&A
B10: Effective tax rate | C10: decimal e.g. 0.25 | E10: Tax note
B11: Net income | C11: currency mn | E11: Income statement
B12: Operating cash flow | C12: currency mn | E12: Cash flow statement
B13: Capital expenditure | C13: currency mn | E13: Cash flow statement — investing
B14: Total debt | C14: currency mn | E14: Balance sheet
B15: Cash & equivalents | C15: currency mn | E15: Balance sheet
B16: Total equity | C16: currency mn | E16: Balance sheet
B17: Interest expense | C17: currency mn | E17: Finance costs note
... B19: Free float | C19: % e.g. 0.35 | E19: Ownership / shareholding note
B21: COMPUTED RATIOS — do not edit, these calculate
B22: Revenue 3-yr CAGR | D22: =IFERROR((D6/D7)^(1/3)-1,"")
B23: ROIC (NOPAT / invested capital) | D23: =IFERROR(D8*(1-D10)/(D14+D16-D15),"")
B24: FCF conversion (OCF-capex)/NI | D24: =IFERROR((D12-D13)/D11,"")
B25: Net debt / EBITDA | D25: =IFERROR((D14-D15)/D9,"")
B26: EBIT interest cover | D26: =IFERROR(D8/D17,"")
B27: EV / EBITDA | D27: =IFERROR((D18+D14-D15)/D9,"")
B29: BUILDOUT TEST — the four gates, now actually tested
B30: B1 Buildout | C30: >=20% of revenue or 3-yr capex tied to a PUBLISHED capacity target | E30: PASS/FAIL + the actual %, and name the programme (e.g. DOE NREP, disclosed fab capex)
B31: B2 Liquidity | C31: 90-day ADTV >= PHP30M (PH) / USD5M (offshore); free float >=20% | E31: PASS/FAIL + the ADTV figure and its source
B32: B3 Solvency | C32: Net debt/EBITDA <=4.0x OR net cash; if net debt positive, interest cover >=2.5x | E32: PASS/FAIL — read it off the computed ratios above
B33: B4 Conduct | C33: No thermal coal >10% of revenue; no UNGC breach; CG disclosure | E33: PASS/FAIL + note any controversy found
B35: FIRST SCORE — replace the assigned score with a derived one
B36: Factor | C36: Weight | D36: Score 0-100 | E36: Evidence you are scoring on
B37: F — Future Relevance | C37: 0.25 | E37: Scale and duration of the buildout; order backlog or contracted capacity
B38: I — Impact on Youth | C38: 0.15 | E38: Directness of link to a named "first"; segment revenue if disclosed
B39: R — Resilient Finances | C39: 0.25 | E39: Use the ROIC, FCF conversion and leverage computed above
B40: S — Sensible Valuation | C40: 0.2 | E40: EV/EBITDA vs the company's own 5-year range
B41: T — Trust & Governance | C41: 0.15 | E41: Free float, related-party transactions, board independence
B42: WEIGHTED CONVICTION SCORE | D42: =IFERROR(SUMPRODUCT(C37:C41,D37:D41),"")
B44: Score currently assumed in the engine | D44: 82
B45: Difference | D45: =IFERROR(D42-D44,"")
B47: SOURCES USED
B48: Source 1
...

Sheet TSM
B2: Taiwan Semiconductor (TSM)
B3: Priority 8 · Fill BLUE cells only · every figure needs a source
B5: RAW FIGURES — pull these from the filing
B6: Revenue, latest FY | C6: currency mn | E6: Income statement
B7: Revenue, 3 years ago | C7: currency mn | E7: Income statement, comparatives
B8: EBIT (operating profit) | C8: currency mn | E8: Income statement
B9: EBITDA | C9: currency mn | E9: Income statement or MD&A
B10: Effective tax rate | C10: decimal e.g. 0.25 | E10: Tax note
B11: Net income | C11: currency mn | E11: Income statement
B12: Operating cash flow | C12: currency mn | E12: Cash flow statement
B13: Capital expenditure | C13: currency mn | E13: Cash flow statement — investing
B14: Total debt | C14: currency mn | E14: Balance sheet
B15: Cash & equivalents | C15: currency mn | E15: Balance sheet
B16: Total equity | C16: currency mn | E16: Balance sheet
B17: Interest expense | C17: currency mn | E17: Finance costs note
... B19: Free float | C19: % e.g. 0.35 | E19: Ownership / shareholding note
B21: COMPUTED RATIOS — do not edit, these calculate
B22: Revenue 3-yr CAGR | D22: =IFERROR((D6/D7)^(1/3)-1,"")
B23: ROIC (NOPAT / invested capital) | D23: =IFERROR(D8*(1-D10)/(D14+D16-D15),"")
B24: FCF conversion (OCF-capex)/NI | D24: =IFERROR((D12-D13)/D11,"")
B25: Net debt / EBITDA | D25: =IFERROR((D14-D15)/D9,"")
B26: EBIT interest cover | D26: =IFERROR(D8/D17,"")
B27: EV / EBITDA | D27: =IFERROR((D18+D14-D15)/D9,"")
B29: BUILDOUT TEST — the four gates, now actually tested
B30: B1 Buildout | C30: >=20% of revenue or 3-yr capex tied to a PUBLISHED capacity target | E30: PASS/FAIL + the actual %, and name the programme (e.g. DOE NREP, disclosed fab capex)
B31: B2 Liquidity | C31: 90-day ADTV >= PHP30M (PH) / USD5M (offshore); free float >=20% | E31: PASS/FAIL + the ADTV figure and its source
B32: B3 Solvency | C32: Net debt/EBITDA <=4.0x OR net cash; if net debt positive, interest cover >=2.5x | E32: PASS/FAIL — read it off the computed ratios above
B33: B4 Conduct | C33: No thermal coal >10% of revenue; no UNGC breach; CG disclosure | E33: PASS/FAIL + note any controversy found
B35: FIRST SCORE — replace the assigned score with a derived one
B36: Factor | C36: Weight | D36: Score 0-100 | E36: Evidence you are scoring on
B37: F — Future Relevance | C37: 0.25 | E37: Scale and duration of the buildout; order backlog or contracted capacity
B38: I — Impact on Youth | C38: 0.15 | E38: Directness of link to a named "first"; segment revenue if disclosed
B39: R — Resilient Finances | C39: 0.25 | E39: Use the ROIC, FCF conversion and leverage computed above
B40: S — Sensible Valuation | C40: 0.2 | E40: EV/EBITDA vs the company's own 5-year range
B41: T — Trust & Governance | C41: 0.15 | E41: Free float, related-party transactions, board independence
B42: WEIGHTED CONVICTION SCORE | D42: =IFERROR(SUMPRODUCT(C37:C41,D37:D41),"")
B44: Score currently assumed in the engine | D44: 86
B45: Difference | D45: =IFERROR(D42-D44,"")
B47: SOURCES USED
B48: Source 1
...

Sheet SE
B2: Sea Limited (SE)
B3: Priority 9 · Fill BLUE cells only · every figure needs a source
B5: RAW FIGURES — pull these from the filing
B6: Revenue, latest FY | C6: currency mn | E6: Income statement
B7: Revenue, 3 years ago | C7: currency mn | E7: Income statement, comparatives
B8: EBIT (operating profit) | C8: currency mn | E8: Income statement
B9: EBITDA | C9: currency mn | E9: Income statement or MD&A
B10: Effective tax rate | C10: decimal e.g. 0.25 | E10: Tax note
B11: Net income | C11: currency mn | E11: Income statement
B12: Operating cash flow | C12: currency mn | E12: Cash flow statement
B13: Capital expenditure | C13: currency mn | E13: Cash flow statement — investing
B14: Total debt | C14: currency mn | E14: Balance sheet
B15: Cash & equivalents | C15: currency mn | E15: Balance sheet
B16: Total equity | C16: currency mn | E16: Balance sheet
B17: Interest expense | C17: currency mn | E17: Finance costs note
... B19: Free float | C19: % e.g. 0.35 | E19: Ownership / shareholding note
B21: COMPUTED RATIOS — do not edit, these calculate
B22: Revenue 3-yr CAGR | D22: =IFERROR((D6/D7)^(1/3)-1,"")
B23: ROIC (NOPAT / invested capital) | D23: =IFERROR(D8*(1-D10)/(D14+D16-D15),"")
B24: FCF conversion (OCF-capex)/NI | D24: =IFERROR((D12-D13)/D11,"")
B25: Net debt / EBITDA | D25: =IFERROR((D14-D15)/D9,"")
B26: EBIT interest cover | D26: =IFERROR(D8/D17,"")
B27: EV / EBITDA | D27: =IFERROR((D18+D14-D15)/D9,"")
B29: BUILDOUT TEST — the four gates, now actually tested
B30: B1 Buildout | C30: >=20% of revenue or 3-yr capex tied to a PUBLISHED capacity target | E30: PASS/FAIL + the actual %, and name the programme (e.g. DOE NREP, disclosed fab capex)
B31: B2 Liquidity | C31: 90-day ADTV >= PHP30M (PH) / USD5M (offshore); free float >=20% | E31: PASS/FAIL + the ADTV figure and its source
B32: B3 Solvency | C32: Net debt/EBITDA <=4.0x OR net cash; if net debt positive, interest cover >=2.5x | E32: PASS/FAIL — read it off the computed ratios above
B33: B4 Conduct | C33: No thermal coal >10% of revenue; no UNGC breach; CG disclosure | E33: PASS/FAIL + note any controversy found
B35: FIRST SCORE — replace the assigned score with a derived one
B36: Factor | C36: Weight | D36: Score 0-100 | E36: Evidence you are scoring on
B37: F — Future Relevance | C37: 0.25 | E37: Scale and duration of the buildout; order backlog or contracted capacity
B38: I — Impact on Youth | C38: 0.15 | E38: Directness of link to a named "first"; segment revenue if disclosed
B39: R — Resilient Finances | C39: 0.25 | E39: Use the ROIC, FCF conversion and leverage computed above
B40: S — Sensible Valuation | C40: 0.2 | E40: EV/EBITDA vs the company's own 5-year range
B41: T — Trust & Governance | C41: 0.15 | E41: Free float, related-party transactions, board independence
B42: WEIGHTED CONVICTION SCORE | D42: =IFERROR(SUMPRODUCT(C37:C41,D37:D41),"")
B44: Score currently assumed in the engine | D44: 72
B45: Difference | D45: =IFERROR(D42-D44,"")
B47: SOURCES USED
B48: Source 1
...

Sheet GRAB
B2: Grab Holdings (GRAB)
B3: Priority 10 · Fill BLUE cells only · every figure needs a source
B5: RAW FIGURES — pull these from the filing
B6: Revenue, latest FY | C6: currency mn | E6: Income statement
B7: Revenue, 3 years ago | C7: currency mn | E7: Income statement, comparatives
B8: EBIT (operating profit) | C8: currency mn | E8: Income statement
B9: EBITDA | C9: currency mn | E9: Income statement or MD&A
B10: Effective tax rate | C10: decimal e.g. 0.25 | E10: Tax note
B11: Net income | C11: currency mn | E11: Income statement
B12: Operating cash flow | C12: currency mn | E12: Cash flow statement
B13: Capital expenditure | C13: currency mn | E13: Cash flow statement — investing
B14: Total debt | C14: currency mn | E14: Balance sheet
B15: Cash & equivalents | C15: currency mn | E15: Balance sheet
B16: Total equity | C16: currency mn | E16: Balance sheet
B17: Interest expense | C17: currency mn | E17: Finance costs note
... B19: Free float | C19: % e.g. 0.35 | E19: Ownership / shareholding note
B21: COMPUTED RATIOS — do not edit, these calculate
B22: Revenue 3-yr CAGR | D22: =IFERROR((D6/D7)^(1/3)-1,"")
B23: ROIC (NOPAT / invested capital) | D23: =IFERROR(D8*(1-D10)/(D14+D16-D15),"")
B24: FCF conversion (OCF-capex)/NI | D24: =IFERROR((D12-D13)/D11,"")
B25: Net debt / EBITDA | D25: =IFERROR((D14-D15)/D9,"")
B26: EBIT interest cover | D26: =IFERROR(D8/D17,"")
B27: EV / EBITDA | D27: =IFERROR((D18+D14-D15)/D9,"")
B29: BUILDOUT TEST — the four gates, now actually tested
B30: B1 Buildout | C30: >=20% of revenue or 3-yr capex tied to a PUBLISHED capacity target | E30: PASS/FAIL + the actual %, and name the programme (e.g. DOE NREP, disclosed fab capex)
B31: B2 Liquidity | C31: 90-day ADTV >= PHP30M (PH) / USD5M (offshore); free float >=20% | E31: PASS/FAIL + the ADTV figure and its source
B32: B3 Solvency | C32: Net debt/EBITDA <=4.0x OR net cash; if net debt positive, interest cover >=2.5x | E32: PASS/FAIL — read it off the computed ratios above
B33: B4 Conduct | C33: No thermal coal >10% of revenue; no UNGC breach; CG disclosure | E33: PASS/FAIL + note any controversy found
B35: FIRST SCORE — replace the assigned score with a derived one
B36: Factor | C36: Weight | D36: Score 0-100 | E36: Evidence you are scoring on
B37: F — Future Relevance | C37: 0.25 | E37: Scale and duration of the buildout; order backlog or contracted capacity
B38: I — Impact on Youth | C38: 0.15 | E38: Directness of link to a named "first"; segment revenue if disclosed
B39: R — Resilient Finances | C39: 0.25 | E39: Use the ROIC, FCF conversion and leverage computed above
B40: S — Sensible Valuation | C40: 0.2 | E40: EV/EBITDA vs the company's own 5-year range
B41: T — Trust & Governance | C41: 0.15 | E41: Free float, related-party transactions, board independence
B42: WEIGHTED CONVICTION SCORE | D42: =IFERROR(SUMPRODUCT(C37:C41,D37:D41),"")
B44: Score currently assumed in the engine | D44: 70
B45: Difference | D45: =IFERROR(D42-D44,"")
B47: SOURCES USED
B48: Source 1
...
